<?xml version="1.0"?>

<sdf version='1.6'>
  <model name='TinyBot'>

    <link name='base_footprint'>
      <pose frame=''>0 0 0 0 -0 0</pose>
      <inertial>
        <pose frame=''>-0.15 0 0.13 0 -0 0</pose>
        <mass>7</mass> <!-- A higher mass causes wheels to spin while attempting to turn when using DART -->
        <inertia>
          <ixx>0.0594508</ixx>
          <ixy>0</ixy>
          <ixz>-2.77556e-17</ixz>
          <iyy>0.150753</iyy>
          <iyz>0</iyz>
          <izz>0.172704</izz>
        </inertia>
      </inertial>
      <collision name='base_footprint_fixed_joint_lump__base_link_collision'>
        <pose frame=''>-0.11 0 0.151 0 -0 0</pose>
        <geometry>
          <box>
            <size>0.398 0.268 0.16</size>
          </box>
        </geometry>
      </collision>
      <collision name='base_footprint_fixed_joint_lump__base_link_collision_1'>
        <pose frame=''>-0.136 0 0.248 0 -0 0</pose>
        <geometry>
          <box>
            <size>0.375 0.268 0.034</size>
          </box>
        </geometry>
      </collision>
      <collision name='base_footprint_fixed_joint_lump__base_link_collision_2'>
        <pose frame=''>-0.279 0.169 0.106 0 -0 0</pose>
        <geometry>
          <box>
            <size>0.1 0.07 0.07</size>
          </box>
        </geometry>
      </collision>
      <collision name='base_footprint_fixed_joint_lump__base_link_collision_3'>
        <pose frame=''>-0.279 -0.169 0.106 0 -0 0</pose>
        <geometry>
          <box>
            <size>0.1 0.07 0.07</size>
          </box>
        </geometry>
      </collision>
      <collision name='base_footprint_fixed_joint_lump__left_caster_wheel_collision_4'>
        <pose frame=''>-0.3 0.169 0.04 0 -0 0</pose>
        <geometry>
          <sphere>
            <radius>0.04</radius>
          </sphere>
        </geometry>
        <surface>
          <contact>
            <ode>
              <kp>1e+08</kp>
              <min_depth>0.005</min_depth>
            </ode>
          </contact>
          <friction>
            <ode>
              <mu>0</mu>
              <mu2>0</mu2>
            </ode>
          </friction>
        </surface>
      </collision>
      <collision name='base_footprint_fixed_joint_lump__raspicam_collision_5'>
        <pose frame=''>0.05 0.085 0.245 0 -1.15192 3.1415</pose>
        <geometry>
          <box>
            <size>0.03 0.026 0.016</size>
          </box>
        </geometry>
      </collision>
      <collision name='base_footprint_fixed_joint_lump__right_caster_wheel_collision_6'>
        <pose frame=''>-0.3 -0.169 0.04 0 -0 0</pose>
        <geometry>
          <sphere>
            <radius>0.04</radius>
          </sphere>
        </geometry>
        <surface>
          <contact>
            <ode>
              <kp>1e+08</kp>
              <min_depth>0.005</min_depth>
            </ode>
          </contact>
          <friction>
            <ode>
              <mu>0</mu>
              <mu2>0</mu2>
            </ode>
          </friction>
        </surface>
      </collision>
      <collision name='base_footprint_fixed_joint_lump__sonar_0_collision_7'>
        <pose frame=''>0.01 -0.14 0.25 0 0 -1.5708</pose>
        <geometry>
          <box>
            <size>0.02 0.044 0.021</size>
          </box>
        </geometry>
        <surface>
          <contact>
            <ode/>
          </contact>
          <friction>
            <ode/>
          </friction>
        </surface>
      </collision>
      <collision name='base_footprint_fixed_joint_lump__sonar_1_collision_8'>
        <pose frame=''>0.08 -0.07 0.25 0 -0 0.785</pose>
        <geometry>
          <box>
            <size>0.02 0.044 0.021</size>
          </box>
        </geometry>
        <surface>
          <contact>
            <ode/>
          </contact>
          <friction>
            <ode/>
          </friction>
        </surface>
      </collision>
      <collision name='base_footprint_fixed_joint_lump__sonar_2_collision_9'>
        <pose frame=''>0.08 -0.01 0.25 0 0 -0.785</pose>
        <geometry>
          <box>
            <size>0.02 0.044 0.021</size>
          </box>
        </geometry>
        <surface>
          <contact>
            <ode/>
          </contact>
          <friction>
            <ode/>
          </friction>
        </surface>
      </collision>
      <collision name='base_footprint_fixed_joint_lump__sonar_3_collision_10'>
        <pose frame=''>0.08 0.04 0.25 0 -0 0</pose>
        <geometry>
          <box>
            <size>0.02 0.044 0.021</size>
          </box>
        </geometry>
        <surface>
          <contact>
            <ode/>
          </contact>
          <friction>
            <ode/>
          </friction>
        </surface>
      </collision>
      <collision name='base_footprint_fixed_joint_lump__sonar_4_collision_11'>
        <pose frame=''>0.01 0.14 0.25 0 -0 1.5708</pose>
        <geometry>
          <box>
            <size>0.02 0.044 0.021</size>
          </box>
        </geometry>
        <surface>
          <contact>
            <ode/>
          </contact>
          <friction>
            <ode/>
          </friction>
        </surface>
      </collision>
      <visual name='base_footprint_fixed_joint_lump__base_link_visual'>
        <pose frame=''>-0.11 0 0.071 0 -0 0</pose>
        <geometry>
          <mesh>
            <scale>1 1 1</scale>
            <uri>model://TinyBot/TinyBot_body.dae</uri>
          </mesh>
        </geometry>
      </visual>
      <visual name='base_footprint_fixed_joint_lump__base_link_visual_1'>
        <pose frame=''>-0.279 0.17 0.09 0 -0 -3.14159</pose>
        <geometry>
          <mesh>
            <scale>1 1 1</scale>
            <uri>model://TinyBot/caster_wheel.dae</uri>
          </mesh>
        </geometry>
      </visual>
      <visual name='base_footprint_fixed_joint_lump__base_link_visual_2'>
        <pose frame=''>-0.279 -0.17 0.09 0 -0 -3.14159</pose>
        <geometry>
          <mesh>
            <scale>1 1 1</scale>
            <uri>model://TinyBot/caster_wheel.dae</uri>
          </mesh>
        </geometry>
      </visual>
      <velocity_decay/>
      <velocity_decay/>
      <velocity_decay/>
      <velocity_decay/>
    </link>

    <gazebo reference="realsense_camera">
            <sensor name="camera" type="depth">
                <visualize>true</visualize>
                <update_rate>60.0</update_rate>
                <camera name="RS_D455">
                    <horizontal_fov>1.047198</horizontal_fov>
                    <image>
                        <width>640</width>
                        <height>480</height>
                        <format>R8G8B8</format>
                    </image>
                    <clip>
                        <near>0.05</near>
                        <far>10</far>
                    </clip>
                </camera>
                <plugin name="depth_camera_controller" filename="libgazebo_ros_camera.so">
                    <baseline>0.2</baseline>
                    <alwaysOn>true</alwaysOn>
                    <updateRate>0.0</updateRate>
                    <frame_name>camera_frame</frame_name>
                    <pointCloudCutoff>0.2</pointCloudCutoff>
                    <pointCloudCutoffMax>10.0</pointCloudCutoffMax>
                    <distortionK1>0</distortionK1>
                    <distortionK2>0</distortionK2>
                    <distortionK3>0</distortionK3>
                    <distortionT1>0</distortionT1>
                    <distortionT2>0</distortionT2>
                    <CxPrime>0</CxPrime>
                    <Cx>0</Cx>
                    <Cy>0</Cy>
                    <focalLength>0</focalLength>
                    <hackBaseline>0</hackBaseline>
                </plugin>
            </sensor>
        </gazebo>


    <link name='left_wheel'>
      <pose frame=''>0 0.163 0.1 0 -0 1.5708</pose>
      <inertial>
        <pose frame=''>0 0 0 3.14159 1.57079 3.14159</pose>
        <mass>3.34</mass>
        <inertia>
          <ixx>0.00904583</ixx>
          <ixy>0</ixy>
          <ixz>0</ixz>
          <iyy>0.00904583</iyy>
          <iyz>0</iyz>
          <izz>0.0167</izz>
        </inertia>
      </inertial>
      <collision name='left_wheel_collision'>
        <pose frame=''>0 0 0 3.14159 1.57079 3.14159</pose>
        <geometry>
          <sphere>
            <radius>0.1</radius>
          </sphere>
        </geometry>
        <surface>
          <contact>
            <ode>
            <!--
              <kp>1e+08</kp>
              <min_depth>0.005</min_depth>
              -->
              <kp>10000000.0</kp>
              <kd>1.0</kd>
            </ode>
          </contact>
          <friction>
            <ode>
              <mu>1</mu>
              <mu2>1</mu2>
              <fdir1>0 0 1</fdir1>
            </ode>
          </friction>
        </surface>
      </collision>
      <visual name='left_wheel_visual'>
        <pose frame=''>-0.071 0 0 0 -0 0</pose>
        <geometry>
          <mesh>
            <scale>1 1 1</scale>
            <uri>model://TinyBot/front_wheel.dae</uri>
          </mesh>
        </geometry>
      </visual>
      <gravity>1</gravity>
      <velocity_decay/>
    </link>
    <joint name='joint_tire_left' type='revolute'>
      <child>left_wheel</child>
      <parent>base_footprint</parent>
      <axis>
        <xyz>0 1 0</xyz>
        <limit>
          <lower>-1e+16</lower>
          <upper>1e+16</upper>
        </limit>
        <dynamics>
          <spring_reference>0</spring_reference>
          <spring_stiffness>0</spring_stiffness>
        </dynamics>
        <use_parent_model_frame>1</use_parent_model_frame>
      </axis>
    </joint>
    <link name='right_wheel'>
      <pose frame=''>0 -0.163 0.1 0 -0 1.5708</pose>
      <inertial>
        <pose frame=''>0 0 0 3.14159 1.57079 3.14159</pose>
        <mass>3.34</mass>
        <inertia>
          <ixx>0.00904583</ixx>
          <ixy>0</ixy>
          <ixz>0</ixz>
          <iyy>0.00904583</iyy>
          <iyz>0</iyz>
          <izz>0.0167</izz>
        </inertia>
      </inertial>
      <collision name='right_wheel_collision'>
        <pose frame=''>0 0 0 3.14159 1.57079 3.14159</pose>
        <geometry>
          <sphere>
            <radius>0.1</radius>
          </sphere>
        </geometry>
        <surface>
          <contact>
            <ode>
            <!--
              <kp>1e+08</kp>
              <min_depth>0.005</min_depth>
              -->
              <kp>10000000.0</kp>
              <kd>1.0</kd>
            </ode>
          </contact>
          <friction>
            <ode>
              <mu>1</mu>
              <mu2>1</mu2>
              <fdir1>0 0 1</fdir1>
            </ode>
          </friction>
        </surface>
      </collision>
      <visual name='right_wheel_visual'>
        <pose frame=''>0.071 0 0 -3.14159 0 -3.14159</pose>
        <geometry>
          <mesh>
            <scale>1 1 1</scale>
            <uri>model://TinyBot/front_wheel.dae</uri>
          </mesh>
        </geometry>
      </visual>
      <gravity>1</gravity>
      <velocity_decay/>
    </link>
    <joint name='joint_tire_right' type='revolute'>
      <child>right_wheel</child>
      <parent>base_footprint</parent>
      <axis>
        <xyz>0 1 0</xyz>
        <limit>
          <lower>-1e+16</lower>
          <upper>1e+16</upper>
        </limit>
        <dynamics>
          <spring_reference>0</spring_reference>
          <spring_stiffness>0</spring_stiffness>
        </dynamics>
        <use_parent_model_frame>1</use_parent_model_frame>
      </axis>
    </joint>
    <static>0</static>

  </model>
</sdf>
